<?xml version="1.0" encoding="UTF-8"?>
<!-- Generated by org.testng.reporters.JUnitReportReporter -->
<testsuite hostname="Potatos-Mac" failures="1" tests="1" name="TestCases.AuthenticationUserSignIn" time="2.594" errors="0" timestamp="2020-04-03T00:15:45 WIB" skipped="0">
  <testcase classname="TestCases.AuthenticationUserSignIn" name="A_001_LoginwithValidCredential" time="2.594">
    <failure message="expected [http://salt-media-cms-dev.s3-website-ap-southeast-1.amazonaws.com/app-pages] but found [http://salt-media-cms-dev.s3-website-ap-southeast-1.amazonaws.com/login]" type="java.lang.AssertionError">
      <![CDATA[java.lang.AssertionError: expected [http://salt-media-cms-dev.s3-website-ap-southeast-1.amazonaws.com/app-pages] but found [http://salt-media-cms-dev.s3-website-ap-southeast-1.amazonaws.com/login]
at org.testng.Assert.fail(Assert.java:97)
at org.testng.Assert.assertEqualsImpl(Assert.java:136)
at org.testng.Assert.assertEquals(Assert.java:118)
at org.testng.Assert.assertEquals(Assert.java:575)
at org.testng.Assert.assertEquals(Assert.java:585)
at TestCases.AuthenticationUserSignIn.A_001_LoginwithValidCredential(AuthenticationUserSignIn.java:31)
at java.base/jdk.internal.reflect.NativeMethodAccessorImpl.invoke0(Native Method)
at java.base/jdk.internal.reflect.NativeMethodAccessorImpl.invoke(NativeMethodAccessorImpl.java:62)
at java.base/jdk.internal.reflect.DelegatingMethodAccessorImpl.invoke(DelegatingMethodAccessorImpl.java:43)
at java.base/java.lang.reflect.Method.invoke(Method.java:564)
at org.testng.internal.MethodInvocationHelper.invokeMethod(MethodInvocationHelper.java:133)
at org.testng.internal.TestInvoker.invokeMethod(TestInvoker.java:584)
at org.testng.internal.TestInvoker.invokeTestMethod(TestInvoker.java:172)
at org.testng.internal.MethodRunner.runInSequence(MethodRunner.java:46)
at org.testng.internal.TestInvoker$MethodInvocationAgent.invoke(TestInvoker.java:804)
at org.testng.internal.TestInvoker.invokeTestMethods(TestInvoker.java:145)
at org.testng.internal.TestMethodWorker.invokeTestMethods(TestMethodWorker.java:146)
at org.testng.internal.TestMethodWorker.run(TestMethodWorker.java:128)
at java.base/java.util.ArrayList.forEach(ArrayList.java:1380)
at org.testng.TestRunner.privateRun(TestRunner.java:770)
at org.testng.TestRunner.run(TestRunner.java:591)
at org.testng.SuiteRunner.runTest(SuiteRunner.java:402)
at org.testng.SuiteRunner.access$000(SuiteRunner.java:41)
at org.testng.SuiteRunner$SuiteWorker.run(SuiteRunner.java:443)
at org.testng.internal.thread.ThreadUtil.lambda$execute$0(ThreadUtil.java:67)
at java.base/java.util.concurrent.FutureTask.run(FutureTask.java:264)
at java.base/java.util.concurrent.ThreadPoolExecutor.runWorker(ThreadPoolExecutor.java:1167)
at java.base/java.util.concurrent.ThreadPoolExecutor$Worker.run(ThreadPoolExecutor.java:641)
at java.base/java.lang.Thread.run(Thread.java:844)
]]>
    </failure>
  </testcase> <!-- A_001_LoginwithValidCredential -->
</testsuite> <!-- TestCases.AuthenticationUserSignIn -->
